<?xml version='1.0' encoding='utf-8'?>
<robot name="twheel">
  <link name="base_footprint"/>
  <link name="base_link">
    <visual>
      <origin xyz="0.0 0.0 -0.018" rpy="0.0 0.0 1.57079632679"/>
      <geometry>
        <mesh filename="package://twheel_description/meshes/coconut.stl"/>
      </geometry>
      <material name="chassis_color">
        <color rgba="1.0 1.0 1.0 1.0"/>
      </material>
    </visual>   
  </link>
  
  <link name="left_wheel">
    <visual>
      <origin xyz="0.0 0.0 0.0" rpy="0.0 0.0 0.0"/>
        <geometry>
          <cylinder radius="0.08" length="0.04"/>
        </geometry>
        <material name="left_wheel_color">
          <color rgba="0.0 0.0 0.0 1.0"/>
        </material>
    </visual>
  </link>

  <link name="right_wheel">
    <visual>
      <origin xyz="0.0 0.0 0.0" rpy="0.0 0.0 0.0"/>
        <geometry>
          <cylinder radius="0.08" length="0.04"/>
        </geometry>
        <material name="right_wheel_color">
          <color rgba="0.0 0.0 0.0 1.0"/>
        </material>
    </visual>
  </link>

  <joint name="base_offset" type="fixed">
    <parent link="base_footprint"/>
    <child link="base_link"/>
    <origin xyz="0.0 0.0 0.165"/>    
  </joint>
  <joint name="left_wheel_joint" type="continuous">
    <origin xyz="0.0 0.225 -0.085" rpy="-1.57079632679 0.0 0.0"/>
    <parent link="base_link"/>
    <child link="left_wheel"/>
    <axis xyz="0.0 0.0 1.0"/>
    <joint_properties damping="1.0" friction="1.0"/>
  </joint>
  <joint name="right_wheel_joint" type="continuous">
    <origin xyz="0.0 -0.225 -0.085" rpy="-1.57079632679 0.0 0.0"/>
    <parent link="base_link"/>
    <child link="right_wheel"/>
    <axis xyz="0.0 0.0 1.0"/>
    <joint_properties damping="1.0" friction="1.0"/>
  </joint>

</robot>
